Failure # 1 (occurred at 2024-06-19_03-17-32)
Traceback (most recent call last):
  File "/home/ksairos/anaconda3/envs/rl_final/lib/python3.8/site-packages/ray/tune/trial_runner.py", line 1117, in _process_trial_restore
    self.trial_executor.fetch_result(trial)
  File "/home/ksairos/anaconda3/envs/rl_final/lib/python3.8/site-packages/ray/tune/ray_trial_executor.py", line 788, in fetch_result
    result = ray.get(trial_future[0], timeout=DEFAULT_GET_TIMEOUT)
  File "/home/ksairos/anaconda3/envs/rl_final/lib/python3.8/site-packages/ray/_private/client_mode_hook.py", line 105, in wrapper
    return func(*args, **kwargs)
  File "/home/ksairos/anaconda3/envs/rl_final/lib/python3.8/site-packages/ray/worker.py", line 1625, in get
    raise value.as_instanceof_cause()
ray.exceptions.RayTaskError(TypeError): [36mray::MAPPOTrainer.restore_from_object()[39m (pid=359900, ip=172.26.35.186, repr=MAPPOTrainer)
  File "/home/ksairos/anaconda3/envs/rl_final/lib/python3.8/site-packages/ray/tune/trainable.py", line 433, in restore_from_object
    self.restore(checkpoint_path)
  File "/home/ksairos/anaconda3/envs/rl_final/lib/python3.8/site-packages/ray/tune/trainable.py", line 411, in restore
    self.load_checkpoint(checkpoint_path)
  File "/home/ksairos/anaconda3/envs/rl_final/lib/python3.8/site-packages/ray/rllib/agents/trainer.py", line 830, in load_checkpoint
    self.__setstate__(extra_data)
  File "/home/ksairos/anaconda3/envs/rl_final/lib/python3.8/site-packages/ray/rllib/agents/trainer_template.py", line 289, in __setstate__
    Trainer.__setstate__(self, state)
  File "/home/ksairos/anaconda3/envs/rl_final/lib/python3.8/site-packages/ray/rllib/agents/trainer.py", line 1813, in __setstate__
    self.workers.local_worker().restore(state["worker"])
  File "/home/ksairos/anaconda3/envs/rl_final/lib/python3.8/site-packages/ray/rllib/evaluation/rollout_worker.py", line 1274, in restore
    objs = pickle.loads(objs)
TypeError: an integer is required (got type bytes)

